[2022-11-02T20:04:27.605+0700] {taskinstance.py:1165} INFO - Dependencies all met for <TaskInstance: postgres_dag.insert_into_table manual__2022-11-02T11:22:44.475906+00:00 [queued]>
[2022-11-02T20:04:27.610+0700] {taskinstance.py:1165} INFO - Dependencies all met for <TaskInstance: postgres_dag.insert_into_table manual__2022-11-02T11:22:44.475906+00:00 [queued]>
[2022-11-02T20:04:27.610+0700] {taskinstance.py:1362} INFO - 
--------------------------------------------------------------------------------
[2022-11-02T20:04:27.610+0700] {taskinstance.py:1363} INFO - Starting attempt 3 of 6
[2022-11-02T20:04:27.610+0700] {taskinstance.py:1364} INFO - 
--------------------------------------------------------------------------------
[2022-11-02T20:04:27.620+0700] {taskinstance.py:1383} INFO - Executing <Task(PostgresOperator): insert_into_table> on 2022-11-02 11:22:44.475906+00:00
[2022-11-02T20:04:27.622+0700] {standard_task_runner.py:55} INFO - Started process 4839 to run task
[2022-11-02T20:04:27.624+0700] {standard_task_runner.py:82} INFO - Running: ['airflow', 'tasks', 'run', 'postgres_dag', 'insert_into_table', 'manual__2022-11-02T11:22:44.475906+00:00', '--job-id', '63', '--raw', '--subdir', 'DAGS_FOLDER/dag_with_postgres.py', '--cfg-path', '/tmp/tmpdvwszkz4']
[2022-11-02T20:04:27.625+0700] {standard_task_runner.py:83} INFO - Job 63: Subtask insert_into_table
[2022-11-02T20:04:27.659+0700] {task_command.py:376} INFO - Running <TaskInstance: postgres_dag.insert_into_table manual__2022-11-02T11:22:44.475906+00:00 [running]> on host ginraca-VirtualBox
[2022-11-02T20:04:27.692+0700] {taskinstance.py:1590} INFO - Exporting the following env vars:
AIRFLOW_CTX_DAG_OWNER=admin
AIRFLOW_CTX_DAG_ID=postgres_dag
AIRFLOW_CTX_TASK_ID=insert_into_table
AIRFLOW_CTX_EXECUTION_DATE=2022-11-02T11:22:44.475906+00:00
AIRFLOW_CTX_TRY_NUMBER=3
AIRFLOW_CTX_DAG_RUN_ID=manual__2022-11-02T11:22:44.475906+00:00
[2022-11-02T20:04:27.695+0700] {base.py:71} INFO - Using connection ID 'postgres_localhost' for task execution.
[2022-11-02T20:04:27.708+0700] {sql.py:315} INFO - Running statement: 
            insert into dag_runs(dt, dag_id)
            values ('2022-11-02', 'postgres_dag')
        , parameters: None
[2022-11-02T20:04:27.710+0700] {taskinstance.py:1851} ERROR - Task failed with exception
Traceback (most recent call last):
  File "/home/ginraca/Documents/DatEng/airflow-tutorial/env/lib/python3.10/site-packages/airflow/providers/postgres/operators/postgres.py", line 94, in execute
    self.hook.run(self.sql, self.autocommit, parameters=self.parameters)
  File "/home/ginraca/Documents/DatEng/airflow-tutorial/env/lib/python3.10/site-packages/airflow/providers/common/sql/hooks/sql.py", line 295, in run
    self._run_command(cur, sql_statement, parameters)
  File "/home/ginraca/Documents/DatEng/airflow-tutorial/env/lib/python3.10/site-packages/airflow/providers/common/sql/hooks/sql.py", line 320, in _run_command
    cur.execute(sql_statement)
psycopg2.errors.UniqueViolation: duplicate key value violates unique constraint "dag_runs_pkey"
DETAIL:  Key (dt, dag_id)=(2022-11-02, postgres_dag) already exists.

[2022-11-02T20:04:27.713+0700] {taskinstance.py:1401} INFO - Marking task as UP_FOR_RETRY. dag_id=postgres_dag, task_id=insert_into_table, execution_date=20221102T112244, start_date=20221102T130427, end_date=20221102T130427
[2022-11-02T20:04:27.724+0700] {standard_task_runner.py:100} ERROR - Failed to execute job 63 for task insert_into_table (duplicate key value violates unique constraint "dag_runs_pkey"
DETAIL:  Key (dt, dag_id)=(2022-11-02, postgres_dag) already exists.
; 4839)
[2022-11-02T20:04:27.759+0700] {local_task_job.py:164} INFO - Task exited with return code 1
[2022-11-02T20:04:27.768+0700] {local_task_job.py:273} INFO - 0 downstream tasks scheduled from follow-on schedule check
