[2022-11-02T18:22:34.542+0700] {taskinstance.py:1165} INFO - Dependencies all met for <TaskInstance: postgres_dag.insert_into_table manual__2022-11-02T11:21:27.731171+00:00 [queued]>
[2022-11-02T18:22:34.549+0700] {taskinstance.py:1165} INFO - Dependencies all met for <TaskInstance: postgres_dag.insert_into_table manual__2022-11-02T11:21:27.731171+00:00 [queued]>
[2022-11-02T18:22:34.549+0700] {taskinstance.py:1362} INFO - 
--------------------------------------------------------------------------------
[2022-11-02T18:22:34.549+0700] {taskinstance.py:1363} INFO - Starting attempt 2 of 6
[2022-11-02T18:22:34.549+0700] {taskinstance.py:1364} INFO - 
--------------------------------------------------------------------------------
[2022-11-02T18:22:34.563+0700] {taskinstance.py:1383} INFO - Executing <Task(PostgresOperator): insert_into_table> on 2022-11-02 11:21:27.731171+00:00
[2022-11-02T18:22:34.565+0700] {standard_task_runner.py:55} INFO - Started process 99438 to run task
[2022-11-02T18:22:34.569+0700] {standard_task_runner.py:82} INFO - Running: ['airflow', 'tasks', 'run', 'postgres_dag', 'insert_into_table', 'manual__2022-11-02T11:21:27.731171+00:00', '--job-id', '55', '--raw', '--subdir', 'DAGS_FOLDER/dag_with_postgres.py', '--cfg-path', '/tmp/tmpvj04nbfi']
[2022-11-02T18:22:34.570+0700] {standard_task_runner.py:83} INFO - Job 55: Subtask insert_into_table
[2022-11-02T18:22:34.611+0700] {task_command.py:376} INFO - Running <TaskInstance: postgres_dag.insert_into_table manual__2022-11-02T11:21:27.731171+00:00 [running]> on host ginraca-VirtualBox
[2022-11-02T18:22:34.652+0700] {taskinstance.py:1590} INFO - Exporting the following env vars:
AIRFLOW_CTX_DAG_OWNER=admin
AIRFLOW_CTX_DAG_ID=postgres_dag
AIRFLOW_CTX_TASK_ID=insert_into_table
AIRFLOW_CTX_EXECUTION_DATE=2022-11-02T11:21:27.731171+00:00
AIRFLOW_CTX_TRY_NUMBER=2
AIRFLOW_CTX_DAG_RUN_ID=manual__2022-11-02T11:21:27.731171+00:00
[2022-11-02T18:22:34.655+0700] {base.py:71} INFO - Using connection ID 'postgres_localhost' for task execution.
[2022-11-02T18:22:34.672+0700] {sql.py:315} INFO - Running statement: 
            insert into dag_runs(dt, dag_id)
            values ('2022-11-02', 'postgres_dag')
        , parameters: None
[2022-11-02T18:22:34.674+0700] {taskinstance.py:1851} ERROR - Task failed with exception
Traceback (most recent call last):
  File "/home/ginraca/Documents/DatEng/airflow-tutorial/env/lib/python3.10/site-packages/airflow/providers/postgres/operators/postgres.py", line 94, in execute
    self.hook.run(self.sql, self.autocommit, parameters=self.parameters)
  File "/home/ginraca/Documents/DatEng/airflow-tutorial/env/lib/python3.10/site-packages/airflow/providers/common/sql/hooks/sql.py", line 295, in run
    self._run_command(cur, sql_statement, parameters)
  File "/home/ginraca/Documents/DatEng/airflow-tutorial/env/lib/python3.10/site-packages/airflow/providers/common/sql/hooks/sql.py", line 320, in _run_command
    cur.execute(sql_statement)
psycopg2.errors.UniqueViolation: duplicate key value violates unique constraint "dag_runs_pkey"
DETAIL:  Key (dt, dag_id)=(2022-11-02, postgres_dag) already exists.

[2022-11-02T18:22:34.677+0700] {taskinstance.py:1401} INFO - Marking task as UP_FOR_RETRY. dag_id=postgres_dag, task_id=insert_into_table, execution_date=20221102T112127, start_date=20221102T112234, end_date=20221102T112234
[2022-11-02T18:22:34.689+0700] {standard_task_runner.py:100} ERROR - Failed to execute job 55 for task insert_into_table (duplicate key value violates unique constraint "dag_runs_pkey"
DETAIL:  Key (dt, dag_id)=(2022-11-02, postgres_dag) already exists.
; 99438)
[2022-11-02T18:22:34.701+0700] {local_task_job.py:164} INFO - Task exited with return code 1
[2022-11-02T18:22:34.711+0700] {local_task_job.py:273} INFO - 0 downstream tasks scheduled from follow-on schedule check
