[2022-11-02T18:20:48.971+0700] {taskinstance.py:1165} INFO - Dependencies all met for <TaskInstance: postgres_dag.insert_into_table manual__2022-11-02T11:20:45.045806+00:00 [queued]>
[2022-11-02T18:20:48.976+0700] {taskinstance.py:1165} INFO - Dependencies all met for <TaskInstance: postgres_dag.insert_into_table manual__2022-11-02T11:20:45.045806+00:00 [queued]>
[2022-11-02T18:20:48.977+0700] {taskinstance.py:1362} INFO - 
--------------------------------------------------------------------------------
[2022-11-02T18:20:48.977+0700] {taskinstance.py:1363} INFO - Starting attempt 1 of 6
[2022-11-02T18:20:48.977+0700] {taskinstance.py:1364} INFO - 
--------------------------------------------------------------------------------
[2022-11-02T18:20:49.005+0700] {taskinstance.py:1383} INFO - Executing <Task(PostgresOperator): insert_into_table> on 2022-11-02 11:20:45.045806+00:00
[2022-11-02T18:20:49.007+0700] {standard_task_runner.py:55} INFO - Started process 98621 to run task
[2022-11-02T18:20:49.010+0700] {standard_task_runner.py:82} INFO - Running: ['airflow', 'tasks', 'run', 'postgres_dag', 'insert_into_table', 'manual__2022-11-02T11:20:45.045806+00:00', '--job-id', '51', '--raw', '--subdir', 'DAGS_FOLDER/dag_with_postgres.py', '--cfg-path', '/tmp/tmpv2b72h8e']
[2022-11-02T18:20:49.011+0700] {standard_task_runner.py:83} INFO - Job 51: Subtask insert_into_table
[2022-11-02T18:20:49.062+0700] {task_command.py:376} INFO - Running <TaskInstance: postgres_dag.insert_into_table manual__2022-11-02T11:20:45.045806+00:00 [running]> on host ginraca-VirtualBox
[2022-11-02T18:20:49.083+0700] {abstractoperator.py:417} ERROR - Exception rendering Jinja template for task 'insert_into_table', field 'sql'. Template: "\n            insert into dag_runs(dt, dag_id)\n            values ('{{ ds }}', '{{ dag.id }}')\n        "
Traceback (most recent call last):
  File "/home/ginraca/Documents/DatEng/airflow-tutorial/env/lib/python3.10/site-packages/airflow/models/abstractoperator.py", line 410, in _do_render_template_fields
    rendered_content = self.render_template(
  File "/home/ginraca/Documents/DatEng/airflow-tutorial/env/lib/python3.10/site-packages/airflow/models/abstractoperator.py", line 474, in render_template
    return render_template_to_string(template, context)
  File "/home/ginraca/Documents/DatEng/airflow-tutorial/env/lib/python3.10/site-packages/airflow/utils/helpers.py", line 288, in render_template_to_string
    return render_template(template, cast(MutableMapping[str, Any], context), native=False)
  File "/home/ginraca/Documents/DatEng/airflow-tutorial/env/lib/python3.10/site-packages/airflow/utils/helpers.py", line 283, in render_template
    return "".join(nodes)
  File "<template>", line 16, in root
  File "/home/ginraca/Documents/DatEng/airflow-tutorial/env/lib/python3.10/site-packages/jinja2/runtime.py", line 852, in _fail_with_undefined_error
    raise self._undefined_exception(self._undefined_message)
jinja2.exceptions.UndefinedError: 'airflow.models.dag.DAG object' has no attribute 'id'
[2022-11-02T18:20:49.090+0700] {taskinstance.py:1851} ERROR - Task failed with exception
Traceback (most recent call last):
  File "/home/ginraca/Documents/DatEng/airflow-tutorial/env/lib/python3.10/site-packages/airflow/models/taskinstance.py", line 1457, in _run_raw_task
    self._execute_task_with_callbacks(context, test_mode)
  File "/home/ginraca/Documents/DatEng/airflow-tutorial/env/lib/python3.10/site-packages/airflow/models/taskinstance.py", line 1576, in _execute_task_with_callbacks
    task_orig = self.render_templates(context=context)
  File "/home/ginraca/Documents/DatEng/airflow-tutorial/env/lib/python3.10/site-packages/airflow/models/taskinstance.py", line 2199, in render_templates
    original_task.render_template_fields(context)
  File "/home/ginraca/Documents/DatEng/airflow-tutorial/env/lib/python3.10/site-packages/airflow/models/baseoperator.py", line 1193, in render_template_fields
    self._do_render_template_fields(self, self.template_fields, context, jinja_env, set())
  File "/home/ginraca/Documents/DatEng/airflow-tutorial/env/lib/python3.10/site-packages/airflow/utils/session.py", line 75, in wrapper
    return func(*args, session=session, **kwargs)
  File "/home/ginraca/Documents/DatEng/airflow-tutorial/env/lib/python3.10/site-packages/airflow/models/abstractoperator.py", line 410, in _do_render_template_fields
    rendered_content = self.render_template(
  File "/home/ginraca/Documents/DatEng/airflow-tutorial/env/lib/python3.10/site-packages/airflow/models/abstractoperator.py", line 474, in render_template
    return render_template_to_string(template, context)
  File "/home/ginraca/Documents/DatEng/airflow-tutorial/env/lib/python3.10/site-packages/airflow/utils/helpers.py", line 288, in render_template_to_string
    return render_template(template, cast(MutableMapping[str, Any], context), native=False)
  File "/home/ginraca/Documents/DatEng/airflow-tutorial/env/lib/python3.10/site-packages/airflow/utils/helpers.py", line 283, in render_template
    return "".join(nodes)
  File "<template>", line 16, in root
  File "/home/ginraca/Documents/DatEng/airflow-tutorial/env/lib/python3.10/site-packages/jinja2/runtime.py", line 852, in _fail_with_undefined_error
    raise self._undefined_exception(self._undefined_message)
jinja2.exceptions.UndefinedError: 'airflow.models.dag.DAG object' has no attribute 'id'
[2022-11-02T18:20:49.093+0700] {taskinstance.py:1401} INFO - Marking task as UP_FOR_RETRY. dag_id=postgres_dag, task_id=insert_into_table, execution_date=20221102T112045, start_date=20221102T112048, end_date=20221102T112049
[2022-11-02T18:20:49.102+0700] {standard_task_runner.py:100} ERROR - Failed to execute job 51 for task insert_into_table ('airflow.models.dag.DAG object' has no attribute 'id'; 98621)
[2022-11-02T18:20:49.145+0700] {local_task_job.py:164} INFO - Task exited with return code 1
[2022-11-02T18:20:49.155+0700] {local_task_job.py:273} INFO - 0 downstream tasks scheduled from follow-on schedule check
